2019-02-18 15:24:59,138 ERROR: Exception on /login [GET] [in c:\users\lenovo\appdata\local\programs\python\python37-32\lib\site-packages\flask\app.py:1761]
Traceback (most recent call last):
  File "c:\users\lenovo\appdata\local\programs\python\python37-32\lib\site-packages\flask\app.py", line 1813, in full_dispatch_request
    rv = self.dispatch_request()
  File "c:\users\lenovo\appdata\local\programs\python\python37-32\lib\site-packages\flask\app.py", line 1791, in dispatch_request
    self.raise_routing_exception(req)
  File "c:\users\lenovo\appdata\local\programs\python\python37-32\lib\site-packages\flask\app.py", line 1774, in raise_routing_exception
    raise request.routing_exception
  File "c:\users\lenovo\appdata\local\programs\python\python37-32\lib\site-packages\flask\ctx.py", line 336, in match_request
    self.url_adapter.match(return_rule=True)
  File "c:\users\lenovo\appdata\local\programs\python\python37-32\lib\site-packages\werkzeug\routing.py", line 1581, in match
    raise NotFound()
werkzeug.exceptions.NotFound: 404 Not Found: The requested URL was not found on the server.  If you entered the URL manually please check your spelling and try again.

During handling of the above exception, another exception occurred:

Traceback (most recent call last):
  File "c:\users\lenovo\appdata\local\programs\python\python37-32\lib\site-packages\flask\app.py", line 2292, in wsgi_app
    response = self.full_dispatch_request()
  File "c:\users\lenovo\appdata\local\programs\python\python37-32\lib\site-packages\flask\app.py", line 1815, in full_dispatch_request
    rv = self.handle_user_exception(e)
  File "c:\users\lenovo\appdata\local\programs\python\python37-32\lib\site-packages\flask\app.py", line 1713, in handle_user_exception
    return self.handle_http_exception(e)
  File "c:\users\lenovo\appdata\local\programs\python\python37-32\lib\site-packages\flask\app.py", line 1644, in handle_http_exception
    return handler(e)
  File "C:\Users\lenovo\microblog\app\errors\handlers.py", line 8, in not_found_error
    return render_template('errors/404.html'), 404
  File "c:\users\lenovo\appdata\local\programs\python\python37-32\lib\site-packages\flask\templating.py", line 135, in render_template
    context, ctx.app)
  File "c:\users\lenovo\appdata\local\programs\python\python37-32\lib\site-packages\flask\templating.py", line 117, in _render
    rv = template.render(context)
  File "c:\users\lenovo\appdata\local\programs\python\python37-32\lib\site-packages\jinja2\asyncsupport.py", line 76, in render
    return original_render(self, *args, **kwargs)
  File "c:\users\lenovo\appdata\local\programs\python\python37-32\lib\site-packages\jinja2\environment.py", line 1008, in render
    return self.environment.handle_exception(exc_info, True)
  File "c:\users\lenovo\appdata\local\programs\python\python37-32\lib\site-packages\jinja2\environment.py", line 780, in handle_exception
    reraise(exc_type, exc_value, tb)
  File "c:\users\lenovo\appdata\local\programs\python\python37-32\lib\site-packages\jinja2\_compat.py", line 37, in reraise
    raise value.with_traceback(tb)
  File "C:\Users\lenovo\microblog\app\templates\errors\404.html", line 1, in top-level template code
    {% extends "base.html" %}
  File "C:\Users\lenovo\microblog\app\templates\base.html", line 1, in top-level template code
    {% extends 'bootstrap/base.html' %}
  File "c:\users\lenovo\appdata\local\programs\python\python37-32\lib\site-packages\flask_bootstrap\templates\bootstrap\base.html", line 1, in top-level template code
    {% block doc -%}
  File "c:\users\lenovo\appdata\local\programs\python\python37-32\lib\site-packages\flask_bootstrap\templates\bootstrap\base.html", line 4, in block "doc"
    {%- block html %}
  File "c:\users\lenovo\appdata\local\programs\python\python37-32\lib\site-packages\flask_bootstrap\templates\bootstrap\base.html", line 20, in block "html"
    {% block body -%}
  File "c:\users\lenovo\appdata\local\programs\python\python37-32\lib\site-packages\flask_bootstrap\templates\bootstrap\base.html", line 23, in block "body"
    {% block content -%}
  File "C:\Users\lenovo\microblog\app\templates\base.html", line 56, in block "content"
    {% if current_user.is_authenticated %}
jinja2.exceptions.UndefinedError: 'app.models.User object' has no attribute 'get_tasks_in_progress'
2019-02-18 15:24:59,198 ERROR: Exception on /favicon.ico [GET] [in c:\users\lenovo\appdata\local\programs\python\python37-32\lib\site-packages\flask\app.py:1761]
Traceback (most recent call last):
  File "c:\users\lenovo\appdata\local\programs\python\python37-32\lib\site-packages\flask\app.py", line 1813, in full_dispatch_request
    rv = self.dispatch_request()
  File "c:\users\lenovo\appdata\local\programs\python\python37-32\lib\site-packages\flask\app.py", line 1791, in dispatch_request
    self.raise_routing_exception(req)
  File "c:\users\lenovo\appdata\local\programs\python\python37-32\lib\site-packages\flask\app.py", line 1774, in raise_routing_exception
    raise request.routing_exception
  File "c:\users\lenovo\appdata\local\programs\python\python37-32\lib\site-packages\flask\ctx.py", line 336, in match_request
    self.url_adapter.match(return_rule=True)
  File "c:\users\lenovo\appdata\local\programs\python\python37-32\lib\site-packages\werkzeug\routing.py", line 1581, in match
    raise NotFound()
werkzeug.exceptions.NotFound: 404 Not Found: The requested URL was not found on the server.  If you entered the URL manually please check your spelling and try again.

During handling of the above exception, another exception occurred:

Traceback (most recent call last):
  File "c:\users\lenovo\appdata\local\programs\python\python37-32\lib\site-packages\flask\app.py", line 2292, in wsgi_app
    response = self.full_dispatch_request()
  File "c:\users\lenovo\appdata\local\programs\python\python37-32\lib\site-packages\flask\app.py", line 1815, in full_dispatch_request
    rv = self.handle_user_exception(e)
  File "c:\users\lenovo\appdata\local\programs\python\python37-32\lib\site-packages\flask\app.py", line 1713, in handle_user_exception
    return self.handle_http_exception(e)
  File "c:\users\lenovo\appdata\local\programs\python\python37-32\lib\site-packages\flask\app.py", line 1644, in handle_http_exception
    return handler(e)
  File "C:\Users\lenovo\microblog\app\errors\handlers.py", line 8, in not_found_error
    return render_template('errors/404.html'), 404
  File "c:\users\lenovo\appdata\local\programs\python\python37-32\lib\site-packages\flask\templating.py", line 135, in render_template
    context, ctx.app)
  File "c:\users\lenovo\appdata\local\programs\python\python37-32\lib\site-packages\flask\templating.py", line 117, in _render
    rv = template.render(context)
  File "c:\users\lenovo\appdata\local\programs\python\python37-32\lib\site-packages\jinja2\asyncsupport.py", line 76, in render
    return original_render(self, *args, **kwargs)
  File "c:\users\lenovo\appdata\local\programs\python\python37-32\lib\site-packages\jinja2\environment.py", line 1008, in render
    return self.environment.handle_exception(exc_info, True)
  File "c:\users\lenovo\appdata\local\programs\python\python37-32\lib\site-packages\jinja2\environment.py", line 780, in handle_exception
    reraise(exc_type, exc_value, tb)
  File "c:\users\lenovo\appdata\local\programs\python\python37-32\lib\site-packages\jinja2\_compat.py", line 37, in reraise
    raise value.with_traceback(tb)
  File "C:\Users\lenovo\microblog\app\templates\errors\404.html", line 1, in top-level template code
    {% extends "base.html" %}
  File "C:\Users\lenovo\microblog\app\templates\base.html", line 1, in top-level template code
    {% extends 'bootstrap/base.html' %}
  File "c:\users\lenovo\appdata\local\programs\python\python37-32\lib\site-packages\flask_bootstrap\templates\bootstrap\base.html", line 1, in top-level template code
    {% block doc -%}
  File "c:\users\lenovo\appdata\local\programs\python\python37-32\lib\site-packages\flask_bootstrap\templates\bootstrap\base.html", line 4, in block "doc"
    {%- block html %}
  File "c:\users\lenovo\appdata\local\programs\python\python37-32\lib\site-packages\flask_bootstrap\templates\bootstrap\base.html", line 20, in block "html"
    {% block body -%}
  File "c:\users\lenovo\appdata\local\programs\python\python37-32\lib\site-packages\flask_bootstrap\templates\bootstrap\base.html", line 23, in block "body"
    {% block content -%}
  File "C:\Users\lenovo\microblog\app\templates\base.html", line 56, in block "content"
    {% if current_user.is_authenticated %}
jinja2.exceptions.UndefinedError: 'app.models.User object' has no attribute 'get_tasks_in_progress'
2019-02-18 15:42:39,862 INFO: Microblog startup [in C:\Users\lenovo\microblog\app\__init__.py:82]
2019-02-18 15:43:11,343 INFO: Microblog startup [in C:\Users\lenovo\microblog\app\__init__.py:82]
2019-02-18 15:43:14,540 INFO: Microblog startup [in C:\Users\lenovo\microblog\app\__init__.py:82]
